Workbook

Sheet Raw Data
A1: DATE | B1: SERVICE | C1: AMOUNT PAID | D1: CUSTOMER TYPE | E1: CATEGORY
A2: 45474 | B2: Eyebrow Threading | C2: 70 | D2: New | E2: Beauty service
A3: 45474 | B3: Eyebrow Threading | C3: 70 | D3: Repeat | E3: Beauty service
A4: 45475 | B4: Eyebrow Threading | C4: 70 | D4: Repeat | E4: Beauty service
A5: 45477 | B5: Eyebrow Threading | C5: 60 | D5: Repeat | E5: Beauty service
A6: 45480 | B6: Baby shower Makeup | C6: 4500 | D6: Repeat | E6: Beauty service
A7: 45483 | B7: fruit facial | C7: 850 | D7: Repeat | E7: Beauty service
A8: 45483 | B8: Saree prepleat | C8: 140 | D8: Repeat | E8: Beauty service
A9: 45483 | B9: Eyebrow Threading | C9: 60 | D9: Repeat | E9: Beauty service
A10: 45486 | B10: Eyebrow Threading | C10: 60 | D10: New | E10: Beauty service
A11: 45487 | B11: Eyebrow Threading | C11: 60 | D11: New | E11: Beauty service
A12: 45488 | B12: Eyebrow Threading | C12: 60 | D12: Repeat | E12: Beauty service
A13: 45489 | B13: Eyebrow Threading | C13: 60 | D13: Repeat | E13: Beauty service
... A70: 45524 | B70: Eyebrow Threading | C70: 150 | D70: Repeat | E70: Beauty service
A71: 45524 | B71: Eyebrow Threading | D71: Repeat | E71: Beauty service
A72: 45524 | B72: Eyebrow Threading | D72: Repeat | E72: Beauty service
A73: 45525 | B73: straight cut | C73: 300 | D73: Repeat | E73: Beauty service
A74: 45525 | B74: Cleanup | C74: 500 | D74: Repeat | E74: Beauty service
A75: 45525 | B75: Eyebrow Threading | C75: 50 | D75: New | E75: Beauty service
A76: 45525 | B76: Eyebrow Threading | C76: 50 | D76: New | E76: Beauty service
A77: 45526 | B77: Hair coloring | C77: 900 | D77: Repeat | E77: Beauty service
A78: 45526 | B78: Hair coloring | C78: 800 | D78: Repeat | E78: Beauty service
A79: 45527 | B79: Eyebrow Threading | C79: 50 | D79: Repeat | E79: Beauty service
A80: 45527 | B80: Eyebrow Threading | C80: 80 | D80: Repeat | E80: Beauty service
A81: 45527 | B81: Eyebrow Threading | C81: 50 | D81: Repeat | E81: Beauty service
A82: 45527 | B82: Eyebrow Threading | C82: 70 | D82: Repeat | E82: Beauty service
A83: 45527 | B83: Pearl facial | C83: 900 | D83: Repeat | E83: Beauty service
A84: 45528 | B84: Eyebrow Threading | C84: 50 | D84: Repeat | E84: Beauty service
A85: 45530 | B85: Hair coloring | C85: 1900 | D85: Repeat | E85: Beauty service
A86: 45530 | B86: Hair coloring | D86: Repeat | E86: Beauty service
A87: 45530 | B87: Head Massage | D87: Repeat | E87: Beauty service
A88: 45531 | B88: Hair cut | C88: 550 | D88: Repeat | E88: Beauty service
A89: 45531 | B89: Eyebrow Threading | D89: Repeat | E89: Beauty service
A90: 45532 | B90: Eyebrow Threading | C90: 150 | D90: Repeat | E90: Beauty service
A91: 45532 | B91: Eyebrow Threading | D91: Repeat | E91: Beauty service
A92: 45532 | B92: Eyebrow Threading | D92: Repeat | E92: Beauty service
A93: 45533 | B93: Eyebrow Threading | C93: 190 | D93: Repeat | E93: Beauty service
A94: 45533 | B94: Eyebrow Threading | D94: Repeat | E94: Beauty service
A95: 45533 | B95: Eyebrow Threading | D95: Repeat | E95: Beauty service
A96: 45533 | B96: Eyebrow Threading | C96: 70 | D96: Repeat | E96: Beauty service
...

Sheet Price_List
A1: Combined Services Price list | F1: TAILORING SERVICE | J1: BEAUTY SERVICE
A2: SERVICE | B2: MIN PRICE | C2: MAX PRICE | F2: SERVICE | G2: MIN PRICE | H2: MAX PRICE | J2: SERVICE | K2: MIN PRICE | L2: MAX PRICE
A3: Bleach | B3: 350 | C3: 500 | F3: Aari Blouse | G3: 1000 | H3: 6000 | J3: Bleach | K3: 350 | L3: 500
A4: Blowdry | B4: 300 | C4: 500 | F4: Alteration work | G4: 50 | H4: 150 | J4: Blowdry | K4: 300 | L4: 500
A5: Cleanup | B5: 500 | C5: 500 | F5: Blouse | G5: 200 | H5: 300 | J5: Cleanup | K5: 500 | L5: 500
A6: Color apply | B6: 700 | C6: 700 | F6: Bridal Blouse | G6: 500 | H6: 500 | J6: Color apply | K6: 700 | L6: 700
A7: Ear piercing | B7: 600 | C7: 1000 | F7: Chudidhar | G7: 300 | H7: 500 | J7: Ear piercing | K7: 600 | L7: 1000
A8: EBS | B8: 70 | C8: 140 | F8: Fals Stitching | G8: 100 | H8: 300 | J8: EBS | K8: 70 | L8: 140
A9: Eyebrow Threading | B9: 60 | C9: 70 | F9: Machine Embroidery | G9: 500 | H9: 2000 | J9: Eyebrow Threading | K9: 60 | L9: 70
A10: Lice treatment | B10: 1500 | C10: 2000 | F10: Maxi | G10: 600 | H10: 800 | J10: Lice treatment | K10: 1500 | L10: 2000
A11: Pedicure | B11: 600 | C11: 600 | F11: Maxi Aari Work | G11: 1000 | H11: 1500 | J11: Pedicure | K11: 600 | L11: 600
A12: Smoothening | B12: 3000 | C12: 7000 | F12: Oram Stitching | G12: 30 | H12: 40 | J12: Smoothening | K12: 3000 | L12: 7000
A13: Straightening | B13: 900 | C13: 1100 | F13: Pant | G13: 350 | H13: 350 | J13: Straightening | K13: 900 | L13: 1100
A14: Bridal Facial | B14: 2000 | C14: 2000 | F14: Saree Oram | G14: 200 | H14: 500 | J14: Bridal Facial | K14: 2000 | L14: 2000
... A17: Fruit Facial | B17: 800 | C17: 800 | F17: Uniform Stitching | G17: 700 | H17: 1000 | J17: Fruit Facial | K17: 800 | L17: 800
A18: Golden Facial | B18: 1100 | C18: 1100 | J18: Golden Facial | K18: 1100 | L18: 1100
A19: Green Tea Facial | B19: 800 | C19: 800 | J19: Green Tea Facial | K19: 800 | L19: 800
A20: Pearl Facial | B20: 900 | C20: 900 | J20: Pearl Facial | K20: 900 | L20: 900
A21: Vitamin C Facial | B21: 700 | C21: 700 | J21: Vitamin C Facial | K21: 700 | L21: 700
A22: Whitening Facial | B22: 1000 | C22: 1000 | J22: Whitening Facial | K22: 1000 | L22: 1000
A23: Wine Facial | B23: 850 | C23: 850 | J23: Wine Facial | K23: 850 | L23: 850
A24: Baby cut | B24: 150 | C24: 200 | J24: Baby cut | K24: 150 | L24: 200
A25: Basic cut | B25: 250 | C25: 250 | J25: Basic cut | K25: 250 | L25: 250
A26: Butterfly cut | B26: 600 | C26: 600 | J26: Butterfly cut | K26: 600 | L26: 600
A27: Feather cut | B27: 700 | C27: 700 | J27: Feather cut | K27: 700 | L27: 700
A28: Layer cut | B28: 500 | C28: 500 | J28: Layer cut | K28: 500 | L28: 500
A29: Straight cut | B29: 300 | C29: 300 | J29: Straight cut | K29: 300 | L29: 300
... A47: Party Makeup | B47: 3000 | C47: 4000 | J47: Party Makeup | K47: 3000 | L47: 4000
A48: Aari Blouse | B48: 1000 | C48: 6000
A49: Alteration work | B49: 50 | C49: 150
A50: Blouse | B50: 200 | C50: 300
A51: Bridal Blouse | B51: 500 | C51: 500
A52: Chudidhar | B52: 300 | C52: 500
A53: Fals Stitching | B53: 100 | C53: 300
A54: Machine Embroidery | B54: 500 | C54: 2000
A55: Maxi | B55: 600 | C55: 800
A56: Maxi Aari Work | B56: 1000 | C56: 1500
A57: Oram Stitching | B57: 30 | C57: 40
A58: Pant | B58: 350 | C58: 350
A59: Saree Oram | B59: 200 | C59: 500
...

Sheet Cleaned_Data
A1: DATE | B1: SERVICE | C1: AMOUNT_PAID | D1: CUSTOMER_TYPE | E1: CATEGORY | F1: MONTH-YEAR | G1: MONTHNUM | H1: MIN price | I1: MAX price | J1: Pricing Behavior | K1: Revenue Loss
A2: 45474 | B2: Eyebrow Threading | C2: 70 | D2: New | E2: Beauty service | F2: =TEXT(A2, "mmm-yyyy") -> Jul-2024 | G2: =TEXT(A2,"yyyy-mm") -> 2024-07 | H2: =VLOOKUP(B2, Price_List!$A$3:$C$62, 2, FALSE) -> 60 | I2: =VLOOKUP(B2, Price_List!$A$3:$C$62, 3, FALSE) -> 70 | J2: =IF(C2 < H2, "Below Min(Bargain)", IF(C2 > I2, "Above Max", "Within Range")) -> Within Range | K2: =IF(C2 < H2, H2 - C2, 0) -> 0
A3: 45474 | B3: Eyebrow Threading | C3: 70 | D3: Repeat | E3: Beauty service | F3: =TEXT(A3, "mmm-yyyy") -> Jul-2024 | G3: =TEXT(A3,"yyyy-mm") -> 2024-07 | H3: =VLOOKUP(B3, Price_List!$A$3:$C$62, 2, FALSE) -> 60 | I3: =VLOOKUP(B3, Price_List!$A$3:$C$62, 3, FALSE) -> 70 | J3: =IF(C3 < H3, "Below Min(Bargain)", IF(C3 > I3, "Above Max", "Within Range")) -> Within Range | K3: =IF(C3 < H3, H3 - C3, 0) -> 0
A4: 45475 | B4: Eyebrow Threading | C4: 70 | D4: Repeat | E4: Beauty service | F4: =TEXT(A4, "mmm-yyyy") -> Jul-2024 | G4: =TEXT(A4,"yyyy-mm") -> 2024-07 | H4: =VLOOKUP(B4, Price_List!$A$3:$C$62, 2, FALSE) -> 60 | I4: =VLOOKUP(B4, Price_List!$A$3:$C$62, 3, FALSE) -> 70 | J4: =IF(C4 < H4, "Below Min(Bargain)", IF(C4 > I4, "Above Max", "Within Range")) -> Within Range | K4: =IF(C4 < H4, H4 - C4, 0) -> 0
A5: 45477 | B5: Eyebrow Threading | C5: 60 | D5: Repeat | E5: Beauty service | F5: =TEXT(A5, "mmm-yyyy") -> Jul-2024 | G5: =TEXT(A5,"yyyy-mm") -> 2024-07 | H5: =VLOOKUP(B5, Price_List!$A$3:$C$62, 2, FALSE) -> 60 | I5: =VLOOKUP(B5, Price_List!$A$3:$C$62, 3, FALSE) -> 70 | J5: =IF(C5 < H5, "Below Min(Bargain)", IF(C5 > I5, "Above Max", "Within Range")) -> Within Range | K5: =IF(C5 < H5, H5 - C5, 0) -> 0
A6: 45480 | B6: Baby Shower Makeup | C6: 4500 | D6: Repeat | E6: Beauty service | F6: =TEXT(A6, "mmm-yyyy") -> Jul-2024 | G6: =TEXT(A6,"yyyy-mm") -> 2024-07 | H6: =VLOOKUP(B6, Price_List!$A$3:$C$62, 2, FALSE) -> 3000 | I6: =VLOOKUP(B6, Price_List!$A$3:$C$62, 3, FALSE) -> 5000 | J6: =IF(C6 < H6, "Below Min(Bargain)", IF(C6 > I6, "Above Max", "Within Range")) -> Within Range | K6: =IF(C6 < H6, H6 - C6, 0) -> 0
A7: 45483 | B7: Fruit Facial | C7: 850 | D7: Repeat | E7: Beauty service | F7: =TEXT(A7, "mmm-yyyy") -> Jul-2024 | G7: =TEXT(A7,"yyyy-mm") -> 2024-07 | H7: =VLOOKUP(B7, Price_List!$A$3:$C$62, 2, FALSE) -> 800 | I7: =VLOOKUP(B7, Price_List!$A$3:$C$62, 3, FALSE) -> 800 | J7: =IF(C7 < H7, "Below Min(Bargain)", IF(C7 > I7, "Above Max", "Within Range")) -> Above Max | K7: =IF(C7 < H7, H7 - C7, 0) -> 0
A8: 45483 | B8: Saree prepleat | C8: 140 | D8: Repeat | E8: Beauty service | F8: =TEXT(A8, "mmm-yyyy") -> Jul-2024 | G8: =TEXT(A8,"yyyy-mm") -> 2024-07 | H8: =VLOOKUP(B8, Price_List!$A$3:$C$62, 2, FALSE) -> 350 | I8: =VLOOKUP(B8, Price_List!$A$3:$C$62, 3, FALSE) -> 700 | J8: =IF(C8 < H8, "Below Min(Bargain)", IF(C8 > I8, "Above Max", "Within Range")) -> Below Min(Bargain) | K8: =IF(C8 < H8, H8 - C8, 0) -> 210
A9: 45483 | B9: Eyebrow Threading | C9: 60 | D9: Repeat | E9: Beauty service | F9: =TEXT(A9, "mmm-yyyy") -> Jul-2024 | G9: =TEXT(A9,"yyyy-mm") -> 2024-07 | H9: =VLOOKUP(B9, Price_List!$A$3:$C$62, 2, FALSE) -> 60 | I9: =VLOOKUP(B9, Price_List!$A$3:$C$62, 3, FALSE) -> 70 | J9: =IF(C9 < H9, "Below Min(Bargain)", IF(C9 > I9, "Above Max", "Within Range")) -> Within Range | K9: =IF(C9 < H9, H9 - C9, 0) -> 0
A10: 45486 | B10: Eyebrow Threading | C10: 60 | D10: New | E10: Beauty service | F10: =TEXT(A10, "mmm-yyyy") -> Jul-2024 | G10: =TEXT(A10,"yyyy-mm") -> 2024-07 | H10: =VLOOKUP(B10, Price_List!$A$3:$C$62, 2, FALSE) -> 60 | I10: =VLOOKUP(B10, Price_List!$A$3:$C$62, 3, FALSE) -> 70 | J10: =IF(C10 < H10, "Below Min(Bargain)", IF(C10 > I10, "Above Max", "Within Range")) -> Within Range | K10: =IF(C10 < H10, H10 - C10, 0) -> 0
A11: 45487 | B11: Eyebrow Threading | C11: 60 | D11: New | E11: Beauty service | F11: =TEXT(A11, "mmm-yyyy") -> Jul-2024 | G11: =TEXT(A11,"yyyy-mm") -> 2024-07 | H11: =VLOOKUP(B11, Price_List!$A$3:$C$62, 2, FALSE) -> 60 | I11: =VLOOKUP(B11, Price_List!$A$3:$C$62, 3, FALSE) -> 70 | J11: =IF(C11 < H11, "Below Min(Bargain)", IF(C11 > I11, "Above Max", "Within Range")) -> Within Range | K11: =IF(C11 < H11, H11 - C11, 0) -> 0
A12: 45488 | B12: Eyebrow Threading | C12: 60 | D12: Repeat | E12: Beauty service | F12: =TEXT(A12, "mmm-yyyy") -> Jul-2024 | G12: =TEXT(A12,"yyyy-mm") -> 2024-07 | H12: =VLOOKUP(B12, Price_List!$A$3:$C$62, 2, FALSE) -> 60 | I12: =VLOOKUP(B12, Price_List!$A$3:$C$62, 3, FALSE) -> 70 | J12: =IF(C12 < H12, "Below Min(Bargain)", IF(C12 > I12, "Above Max", "Within Range")) -> Within Range | K12: =IF(C12 < H12, H12 - C12, 0) -> 0
A13: 45488 | B13: Bleach | C13: 200 | D13: Repeat | E13: Beauty service | F13: =TEXT(A13, "mmm-yyyy") -> Jul-2024 | G13: =TEXT(A13,"yyyy-mm") -> 2024-07 | H13: =VLOOKUP(B13, Price_List!$A$3:$C$62, 2, FALSE) -> 350 | I13: =VLOOKUP(B13, Price_List!$A$3:$C$62, 3, FALSE) -> 500 | J13: =IF(C13 < H13, "Below Min(Bargain)", IF(C13 > I13, "Above Max", "Within Range")) -> Below Min(Bargain) | K13: =IF(C13 < H13, H13 - C13, 0) -> 150
... A611: 45835 | B611: Bridal Blouse | C611: 500 | D611: Repeat | E611: Tailoring service | F611: =TEXT(A611, "mmm-yyyy") -> Jun-2025 | G611: =TEXT(A611,"yyyy-mm") -> 2025-06 | H611: =VLOOKUP(B611, Price_List!$A$3:$C$62, 2, FALSE) -> 500 | I611: =VLOOKUP(B611, Price_List!$A$3:$C$62, 3, FALSE) -> 500 | J611: =IF(C611 < H611, "Below Min(Bargain)", IF(C611 > I611, "Above Max", "Within Range")) -> Within Range | K611: =IF(C611 < H611, H611 - C611, 0) -> 0

Sheet Business_Statistics
A1: 2024-2025 Beauty service | D1: 2024-2025 beauty service | I1: Tailoring service | N1: BEAUTY SERVICE - ABC ANALYSIS | T1: TAILORING SERVICE - ABC ANALYSIS | Z1: Service-Based Segmentation: New vs Repeat Customers (Beauty) | AE1: Service-Based Segmentation: New vs Repeat Customers (Tailoring) | AJ1: Service-Wise Bargaining Count (Beauty) | AO1: Service-Wise Bargaining Count (Tailoring)
A2: Total Revenue | B2: 214780 | D2: services | E2: Absolute Revenue | F2: % of Total revenue | G2: Cummulative % | I2: services | J2: Absolute Revenue | K2: % of Total revenue | L2: Cummulative % | N2: Services | O2: Revenue | P2: % of Total revenue | Q2: Cumulative | R2: ABC Category | T2: Service | U2: Revenue | V2: % of Total revenue | W2: Cumulative | X2: ABC Category | Z2: Category | AA2: New | AB2: Repeat | AC2: Grand Total | AE2: Category | AF2: New | AG2: Repeat | AH2: Grand Total | AJ2: price behavior | AK2: Above Max | AL2: Below Min(Bargain) | AM2: Within Range | AO2: price behavior | AP2: Above Max | AQ2: Below Min(Bargain) | AR2: Within Range
A3: Average Amount Paid | B3: 407.55218 | D3: Hair coloring | E3: =F3*$B$2 -> 40350 | F3: 0.18786665 | G3: =F3 -> 0.18786665 | I3: Aari Blouse | J3: =K3*$B$22 -> 15200 | K3: 0.38549328 | L3: =K3 -> 0.38549328 | N3: Hair coloring | O3: 40350 | P3: =O3/$O$46 -> 0.18786665 | Q3: =P3 -> 0.18786665 | R3: =IF(Q3<=70%,"A",IF(Q3<=90%,"B","C")) -> A | T3: Aari Blouse | U3: 15200 | V3: =U3/$U$18 -> 0.38549328 | W3: =V3 -> 0.38549328 | X3: =IF(W3<=70%,"A",IF(W3<=90%,"B","C")) -> A | Z3: Eyebrow Threading | AA3: 48 | AB3: 151 | AC3: 199 | AE3: Alteration work | AF3: 8 | AG3: 7 | AH3: 15 | AJ3: Eyebrow Threading | AK3: 39 | AL3: 79 | AM3: 81 | AO3: Maxi | AQ3: 1
A4: Median Amount Paid | B4: 250 | D4: Eyebrow Threading | E4: =F4*$B$2 -> 13820 | F4: 0.064344911 | G4: =G3+F4 -> 0.25221157 | I4: Blouse | J4: =K4*$B$22 -> 6345 | K4: 0.16091808 | L4: =L3+K4 -> 0.54641136 | N4: Eyebrow Threading | O4: 13820 | P4: =O4/$O$46 -> 0.064344911 | Q4: =Q3+P4 -> 0.25221157 | R4: =IF(Q4<=70%,"A",IF(Q4<=90%,"B","C")) -> A | T4: Blouse | U4: 6345 | V4: =U4/$U$18 -> 0.16091808 | W4: =W3+V4 -> 0.54641136 | X4: =IF(W4<=70%,"A",IF(W4<=90%,"B","C")) -> A | Z4: EBS | AA4: 6 | AB4: 41 | AC4: 47 | AE4: Saree Oram | AF4: 6 | AG4: 1 | AH4: 7 | AJ4: Hair coloring | AK4: 2 | AL4: 29 | AM4: 18 | AO4: Blouse | AP4: 6 | AQ4: 1 | AR4: 12
A5: Minimum Amount Paid | B5: 40 | D5: Layer cut | E5: =F5*$B$2 -> 12130 | F5: 0.056476394 | G5: =G4+F5 -> 0.30868796 | I5: Bridal Blouse | J5: =K5*$B$22 -> 5500 | K5: 0.1394877 | L5: =L4+K5 -> 0.68589906 | N5: Layer cut | O5: 12130 | P5: =O5/$O$46 -> 0.056476394 | Q5: =Q4+P5 -> 0.30868796 | R5: =IF(Q5<=70%,"A",IF(Q5<=90%,"B","C")) -> A | T5: Bridal Blouse | U5: 5500 | V5: =U5/$U$18 -> 0.1394877 | W5: =W4+V5 -> 0.68589906 | X5: =IF(W5<=70%,"A",IF(W5<=90%,"B","C")) -> A | Z5: Saree prepleat | AA5: 5 | AB5: 13 | AC5: 18 | AE5: Blouse | AF5: 6 | AG5: 13 | AH5: 19 | AJ5: Color apply | AK5: 1 | AL5: 12 | AM5: 6 | AO5: Alteration work | AP5: 3 | AQ5: 1 | AR5: 11
A6: Maximum Amount Paid | B6: 7000 | D6: Color apply | E6: =F6*$B$2 -> 9760 | F6: 0.045441847 | G6: =G5+F6 -> 0.35412981 | I6: Chudidhar | J6: =K6*$B$22 -> 2650 | K6: 0.06720771 | L6: =L5+K6 -> 0.75310677 | N6: Color apply | O6: 9760 | P6: =O6/$O$46 -> 0.045441847 | Q6: =Q5+P6 -> 0.35412981 | R6: =IF(Q6<=70%,"A",IF(Q6<=90%,"B","C")) -> A | T6: Chudidhar | U6: 2650 | V6: =U6/$U$18 -> 0.06720771 | W6: =W5+V6 -> 0.75310677 | X6: =IF(W6<=70%,"A",IF(W6<=90%,"B","C")) -> B | Z6: Golden Facial | AA6: 4 | AB6: 5 | AC6: 9 | AE6: Sleeve | AF6: 5 | AH6: 5 | AJ6: Layer cut | AL6: 12 | AM6: 14 | AO6: Fals Stitching | AQ6: 1 | AR6: 1
A7: Standard Deviation | B7: 531.01943 | D7: Golden Facial | E7: =F7*$B$2 -> 9500 | F7: 0.044231306 | G7: =G6+F7 -> 0.39836111 | I7: Alteration work | J7: =K7*$B$22 -> 2010 | K7: 0.050976414 | L7: =L6+K7 -> 0.80408319 | N7: Golden Facial | O7: 9500 | P7: =O7/$O$46 -> 0.044231306 | Q7: =Q6+P7 -> 0.39836111 | R7: =IF(Q7<=70%,"A",IF(Q7<=90%,"B","C")) -> A | T7: Alteration work | U7: 2010 | V7: =U7/$U$18 -> 0.050976414 | W7: =W6+V7 -> 0.80408319 | X7: =IF(W7<=70%,"A",IF(W7<=90%,"B","C")) -> B | Z7: Hair coloring | AA7: 4 | AB7: 45 | AC7: 49 | AE7: Aari Blouse | AF7: 5 | AG7: 1 | AH7: 6 | AJ7: De-tan Facial | AL7: 7 | AM7: 1 | AO7: Saree Oram | AR7: 7
A8: Total Services Delivered | B8: 527 | D8: Whitening Facial | E8: =F8*$B$2 -> 8900 | F8: 0.04143775 | G8: =G7+F8 -> 0.43979886 | I8: Saree Oram | J8: =K8*$B$22 -> 1600 | K8: 0.04057824 | L8: =L7+K8 -> 0.84466143 | N8: Whitening Facial | O8: 8900 | P8: =O8/$O$46 -> 0.04143775 | Q8: =Q7+P8 -> 0.43979886 | R8: =IF(Q8<=70%,"A",IF(Q8<=90%,"B","C")) -> A | T8: Saree Oram | U8: 1600 | V8: =U8/$U$18 -> 0.04057824 | W8: =W7+V8 -> 0.84466143 | X8: =IF(W8<=70%,"A",IF(W8<=90%,"B","C")) -> B | Z8: Pearl Facial | AA8: 2 | AB8: 4 | AC8: 6 | AE8: Bridal Blouse | AF8: 4 | AG8: 5 | AH8: 9 | AJ8: Cleanup | AL8: 6 | AM8: 4 | AO8: Oram Stitching | AP8: 4 | AR8: 3
A9: Unique Services Offered | B9: 43 | D9: Baby Shower Makeup | E9: =F9*$B$2 -> 7500 | F9: 0.034919452 | G9: =G8+F9 -> 0.47471832 | I9: Uniform Stitching | J9: =K9*$B$22 -> 1050 | K9: 0.02662947 | L9: =L8+K9 -> 0.8712909 | N9: Baby Shower Makeup | O9: 7500 | P9: =O9/$O$46 -> 0.034919452 | Q9: =Q8+P9 -> 0.47471832 | R9: =IF(Q9<=70%,"A",IF(Q9<=90%,"B","C")) -> A | T9: Uniform Stitching | U9: 1050 | V9: =U9/$U$18 -> 0.02662947 | W9: =W8+V9 -> 0.8712909 | X9: =IF(W9<=70%,"A",IF(W9<=90%,"B","C")) -> B | Z9: Straight cut | AA9: 2 | AB9: 4 | AC9: 6 | AE9: Oram Stitching | AF9: 2 | AG9: 5 | AH9: 7 | AJ9: Golden Facial | AK9: 2 | AL9: 5 | AM9: 2 | AO9: Maxi Aari Work | AR9: 1
D10: De-tan Facial | E10: =F10*$B$2 -> 7050 | F10: 0.032824285 | G10: =G9+F10 -> 0.5075426 | I10: Maxi Aari Work | J10: =K10*$B$22 -> 1000 | K10: 0.0253614 | L10: =L9+K10 -> 0.8966523 | N10: De-tan Facial | O10: 7050 | P10: =O10/$O$46 -> 0.032824285 | Q10: =Q9+P10 -> 0.5075426 | R10: =IF(Q10<=70%,"A",IF(Q10<=90%,"B","C")) -> A | T10: Maxi Aari Work | U10: 1000 | V10: =U10/$U$18 -> 0.0253614 | W10: =W9+V10 -> 0.8966523 | X10: =IF(W10<=70%,"A",IF(W10<=90%,"B","C")) -> B | Z10: Simple Makeup | AA10: 2 | AC10: 2 | AE10: Pant | AF10: 1 | AG10: 1 | AH10: 2 | AJ10: Bleach | AL10: 5 | AM10: 9 | AO10: Sleeve | AR10: 5
A11: Feb - Jun 2025 Beauty service | D11: Bridal Makeup | E11: =F11*$B$2 -> 7000 | F11: 0.032591489 | G11: =G10+F11 -> 0.54013409 | I11: Machine Embroidery | J11: =K11*$B$22 -> 1000 | K11: 0.0253614 | L11: =L10+K11 -> 0.9220137 | N11: Bridal Makeup | O11: 7000 | P11: =O11/$O$46 -> 0.032591489 | Q11: =Q10+P11 -> 0.54013409 | R11: =IF(Q11<=70%,"A",IF(Q11<=90%,"B","C")) -> A | T11: Machine Embroidery | U11: 1000 | V11: =U11/$U$18 -> 0.0253614 | W11: =W10+V11 -> 0.9220137 | X11: =IF(W11<=70%,"A",IF(W11<=90%,"B","C")) -> C | Z11: Fruit Facial | AA11: 2 | AB11: 7 | AC11: 9 | AE11: Maxi | AF11: 1 | AH11: 1 | AJ11: Wine Facial | AK11: 1 | AL11: 5 | AM11: 1 | AO11: Pant | AP11: 1 | AR11: 1
A12: Total Revenue | B12: 88250 | D12: Saree prepleat | E12: =F12*$B$2 -> 6990 | F12: 0.03254493 | G12: =G11+F12 -> 0.57267902 | I12: Sleeve | J12: =K12*$B$22 -> 950 | K12: 0.02409333 | L12: =L11+K12 -> 0.94610703 | N12: Saree prepleat | O12: 6990 | P12: =O12/$O$46 -> 0.03254493 | Q12: =Q11+P12 -> 0.57267902 | R12: =IF(Q12<=70%,"A",IF(Q12<=90%,"B","C")) -> A | T12: Sleeve | U12: 950 | V12: =U12/$U$18 -> 0.02409333 | W12: =W11+V12 -> 0.94610703 | X12: =IF(W12<=70%,"A",IF(W12<=90%,"B","C")) -> C | Z12: Whitening Facial | AA12: 2 | AB12: 7 | AC12: 9 | AE12: Chudidhar | AF12: 1 | AG12: 6 | AH12: 7 | AJ12: Fruit Facial | AK12: 2 | AL12: 4 | AM12: 3 | AO12: Uniform Stitching | AP12: 1
A13: Average Amount Paid | B13: 428.39806 | D13: Fruit Facial | E13: =F13*$B$2 -> 6830 | F13: 0.031799981 | G13: =G12+F13 -> 0.604479 | I13: Pant | J13: =K13*$B$22 -> 780 | K13: 0.019781892 | L13: =L12+K13 -> 0.96588892 | N13: Fruit Facial | O13: 6830 | P13: =O13/$O$46 -> 0.031799981 | Q13: =Q12+P13 -> 0.604479 | R13: =IF(Q13<=70%,"A",IF(Q13<=90%,"B","C")) -> A | T13: Pant | U13: 780 | V13: =U13/$U$18 -> 0.019781892 | W13: =W12+V13 -> 0.96588892 | X13: =IF(W13<=70%,"A",IF(W13<=90%,"B","C")) -> C | Z13: Baby cut | AA13: 2 | AB13: 2 | AC13: 4 | AE13: Fals Stitching | AF13: 1 | AG13: 1 | AH13: 2 | AJ13: Basic cut | AL13: 4 | AM13: 4 | AO13: Chudidhar | AP13: 1 | AR13: 6
A14: Median Amount Paid | B14: 275 | D14: EBS | E14: =F14*$B$2 -> 6450 | F14: 0.030030729 | G14: =G13+F14 -> 0.63450973 | I14: Oram Stitching | J14: =K14*$B$22 -> 690 | K14: 0.017499366 | L14: =L13+K14 -> 0.98338828 | N14: EBS | O14: 6450 | P14: =O14/$O$46 -> 0.030030729 | Q14: =Q13+P14 -> 0.63450973 | R14: =IF(Q14<=70%,"A",IF(Q14<=90%,"B","C")) -> A | T14: Oram Stitching | U14: 690 | V14: =U14/$U$18 -> 0.017499366 | W14: =W13+V14 -> 0.98338828 | X14: =IF(W14<=70%,"A",IF(W14<=90%,"B","C")) -> C | Z14: Hair SPA | AA14: 2 | AB14: 2 | AC14: 4 | AE14: Uniform Stitching | AG14: 1 | AH14: 1 | AJ14: Hand Wax | AL14: 4 | AO14: Bridal Blouse | AP14: 2 | AR14: 7
A15: Minimum Amount Paid | B15: 40 | D15: Wine Facial | E15: =F15*$B$2 -> 5750 | F15: 0.02677158 | G15: =G14+F15 -> 0.66128131 | I15: Maxi | J15: =K15*$B$22 -> 400 | K15: 0.01014456 | L15: =L14+K15 -> 0.99353284 | N15: Wine Facial | O15: 5750 | P15: =O15/$O$46 -> 0.02677158 | Q15: =Q14+P15 -> 0.66128131 | R15: =IF(Q15<=70%,"A",IF(Q15<=90%,"B","C")) -> A | T15: Maxi | U15: 400 | V15: =U15/$U$18 -> 0.01014456 | W15: =W14+V15 -> 0.99353284 | X15: =IF(W15<=70%,"A",IF(W15<=90%,"B","C")) -> C | Z15: Party Makeup | AA15: 1 | AC15: 1 | AE15: Maxi Aari Work | AG15: 1 | AH15: 1 | AJ15: Saree prepleat | AK15: 1 | AL15: 3 | AM15: 14 | AO15: Aari Blouse | AR15: 6
A16: Maximum Amount Paid | B16: 3600 | D16: Hair wash | E16: =F16*$B$2 -> 5300 | F16: 0.024676413 | G16: =G15+F16 -> 0.68595772 | I16: Fals Stitching | J16: =K16*$B$22 -> 255 | K16: 0.006467157 | L16: =L15+K16 -> 1 | N16: Hair wash | O16: 5300 | P16: =O16/$O$46 -> 0.024676413 | Q16: =Q15+P16 -> 0.68595772 | R16: =IF(Q16<=70%,"A",IF(Q16<=90%,"B","C")) -> A | T16: Fals Stitching | U16: 255 | V16: =U16/$U$18 -> 0.006467157 | W16: =W15+V16 -> 1 | X16: =IF(W16<=70%,"A",IF(W16<=90%,"B","C")) -> C | Z16: Head Massage | AA16: 1 | AB16: 5 | AC16: 6 | AE16: Machine Embroidery | AG16: 1 | AH16: 1 | AJ16: Saree drape | AK16: 1 | AL16: 3 | AO16: Machine Embroidery | AR16: 1
A17: Standard Deviation | B17: 489.4256 | D17: Pearl Facial | E17: =F17*$B$2 -> 5270 | F17: 0.024536735 | G17: =G16+F17 -> 0.71049446 | N17: Pearl Facial | O17: 5270 | P17: =O17/$O$46 -> 0.024536735 | Q17: =Q16+P17 -> 0.71049446 | R17: =IF(Q17<=70%,"A",IF(Q17<=90%,"B","C")) -> B | Z17: U cut | AA17: 1 | AB17: 7 | AC17: 8 | AE17: Grand Total | AF17: =SUM(AF3:AF16) -> 40 | AG17: =SUM(AG3:AG16) -> 43 | AH17: =SUM(AH3:AH16) -> 83 | AJ17: Diamond Facial | AL17: 3 | AM17: 2 | AO17: Grand Total | AP17: 18 | AQ17: 4 | AR17: 61
A18: Total Services Delivered | B18: 206 | D18: Diamond Facial | E18: =F18*$B$2 -> 5160 | F18: 0.024024583 | G18: =G17+F18 -> 0.73451904 | I18: Customer Type – Revenue Contribution(Beauty) | N18: Diamond Facial | O18: 5160 | P18: =O18/$O$46 -> 0.024024583 | Q18: =Q17+P18 -> 0.73451904 | R18: =IF(Q18<=70%,"A",IF(Q18<=90%,"B","C")) -> B | T18: Total Revenue | U18: =SUM(U3:U16) -> 39430 | Z18: Basic cut | AA18: 1 | AB18: 7 | AC18: 8 | AJ18: U cut | AK18: 1 | AL18: 2 | AM18: 5
A19: Unique Services Offered | B19: 36 | D19: Bleach | E19: =F19*$B$2 -> 5000 | F19: 0.023279635 | G19: =G18+F19 -> 0.75779868 | I19: Customer type | J19: Revenue | K19: % of Total | N19: Bleach | O19: 5000 | P19: =O19/$O$46 -> 0.023279635 | Q19: =Q18+P19 -> 0.75779868 | R19: =IF(Q19<=70%,"A",IF(Q19<=90%,"B","C")) -> B | Z19: Lice treatment | AA19: 1 | AC19: 1 | AE19: Pricing Behavior - Beauty | AJ19: Pearl Facial | AL19: 2 | AM19: 4 | AO19: Price behavior (New vs repeat) Beauty
D20: Vitamin C Facial | E20: =F20*$B$2 -> 4200 | F20: 0.019554893 | G20: =G19+F20 -> 0.77735357 | I20: New | J20: 34730 | K20: 0.16170034 | N20: Vitamin C Facial | O20: 4200 | P20: =O20/$O$46 -> 0.019554893 | Q20: =Q19+P20 -> 0.77735357 | R20: =IF(Q20<=70%,"A",IF(Q20<=90%,"B","C")) -> B | T20: Monthly Trend analysis-Tailoring | Z20: Face Wax | AA20: 1 | AB20: 4 | AC20: 5 | AE20: price behavior | AF20: Count of Pricing Behavior | AJ20: Bridal Facial | AL20: 2 | AO20: price behavior | AP20: Above Max | AQ20: Below Min(Bargain) | AR20: Within Range
A21: Feb - Jun 2025 Tailoring service | D21: Cleanup | E21: =F21*$B$2 -> 4180 | F21: 0.019461775 | G21: =G20+F21 -> 0.79681535 | I21: Repeat | J21: 180050 | K21: 0.83829966 | N21: Cleanup | O21: 4180 | P21: =O21/$O$46 -> 0.019461775 | Q21: =Q20+P21 -> 0.79681535 | R21: =IF(Q21<=70%,"A",IF(Q21<=90%,"B","C")) -> B | T21: Month-year | U21: New | V21: Repeat | Z21: De-tan Facial | AA21: 1 | AB21: 7 | AC21: 8 | AE21: Above Max | AF21: 72 | AJ21: Hair SPA | AK21: 1 | AL21: 2 | AM21: 1 | AO21: Eyebrow Threading | AP21: 39 | AQ21: 79 | AR21: 81
A22: Total Revenue | B22: 39430 | D22: Simple Makeup | E22: =F22*$B$2 -> 3900 | F22: 0.018158115 | G22: =G21+F22 -> 0.81497346 | I22: Grand Total | J22: 214780 | K22: 1 | N22: Simple Makeup | O22: 3900 | P22: =O22/$O$46 -> 0.018158115 | Q22: =Q21+P22 -> 0.81497346 | R22: =IF(Q22<=70%,"A",IF(Q22<=90%,"B","C")) -> B | T22: Feb-2025 | U22: 25 | V22: 1 | Z22: Hair wash | AA22: 1 | AB22: 10 | AC22: 11 | AE22: Below Min(Bargain) | AF22: 202 | AJ22: Smoothening | AL22: 1 | AO22: New | AP22: 12 | AQ22: 13 | AR22: 23
A23: Average Amount Paid | B23: 475.06024 | D23: Party Makeup | E23: =F23*$B$2 -> 3600 | F23: 0.016761337 | G23: =G22+F23 -> 0.8317348 | N23: Party Makeup | O23: 3600 | P23: =O23/$O$46 -> 0.016761337 | Q23: =Q22+P23 -> 0.8317348 | R23: =IF(Q23<=70%,"A",IF(Q23<=90%,"B","C")) -> B | T23: Mar-2025 | U23: 5 | V23: 3 | Z23: Vitamin C Facial | AA23: 1 | AB23: 5 | AC23: 6 | AE23: Within Range | AF23: 253 | AJ23: Whitening Facial | AL23: 1 | AM23: 8 | AO23: Repeat | AP23: 27 | AQ23: 66 | AR23: 58
A24: Median Amount Paid | B24: 300 | D24: Hair SPA | E24: =F24*$B$2 -> 3570 | F24: 0.016621659 | G24: =G23+F24 -> 0.84835646 | I24: Customer Type – Revenue Contribution(Tailoring) | N24: Hair SPA | O24: 3570 | P24: =O24/$O$46 -> 0.016621659 | Q24: =Q23+P24 -> 0.84835646 | R24: =IF(Q24<=70%,"A",IF(Q24<=90%,"B","C")) -> B | T24: Apr-2025 | U24: 6 | V24: 10 | Z24: Hand Wax | AA24: 1 | AB24: 3 | AC24: 4 | AJ24: Under Arm Wax | AL24: 1 | AO24: Hair coloring | AP24: 2 | AQ24: 29 | AR24: 18
A25: Minimum Amount Paid | B25: 4000 | D25: Green Tea Facial | E25: =F25*$B$2 -> 3200 | F25: 0.014898966 | G25: =G24+F25 -> 0.86325542 | I25: Customer type | J25: Revenue | K25: % of Total | N25: Green Tea Facial | O25: 3200 | P25: =O25/$O$46 -> 0.014898966 | Q25: =Q24+P25 -> 0.86325542 | R25: =IF(Q25<=70%,"A",IF(Q25<=90%,"B","C")) -> B | T25: May-2025 | U25: 2 | V25: 14 | Z25: Layer cut | AA25: 1 | AB25: 25 | AC25: 26 | AE25: Pricing Behavior - Beauty | AJ25: EBS | AK25: 11 | AL25: 1 | AM25: 35 | AO25: New | AQ25: 4
A26: Maximum Amount Paid | B26: 40 | D26: Saree drape | E26: =F26*$B$2 -> 2900 | F26: 0.013502188 | G26: =G25+F26 -> 0.87675761 | I26: New | J26: 23475 | K26: 0.59535886 | N26: Saree drape | O26: 2900 | P26: =O26/$O$46 -> 0.013502188 | Q26: =Q25+P26 -> 0.87675761 | R26: =IF(Q26<=70%,"A",IF(Q26<=90%,"B","C")) -> B | T26: Jun-2025 | U26: 2 | V26: 15 | Z26: Butterfly cut | AB26: 2 | AC26: 2 | AE26: price behavior | AF26: Count of Pricing Behavior | AJ26: Face Wax | AK26: 1 | AL26: 1 | AM26: 3 | AO26: Repeat | AP26: 2 | AQ26: 25 | AR26: 18
A27: Standard Deviation | B27: 657.78939 | D27: Bridal Facial | E27: =F27*$B$2 -> 2760 | F27: 0.012850359 | G27: =G26+F27 -> 0.88960797 | I27: Repeat | J27: 15955 | K27: 0.40464114 | N27: Bridal Facial | O27: 2760 | P27: =O27/$O$46 -> 0.012850359 | Q27: =Q26+P27 -> 0.88960797 | R27: =IF(Q27<=70%,"A",IF(Q27<=90%,"B","C")) -> B | Z27: Color apply | AB27: 19 | AC27: 19 | AE27: Above Max | AF27: 72 | AJ27: Full Arms Wax | AL27: 1 | AO27: Color apply | AP27: 1 | AQ27: 12 | AR27: 6
A28: Total Services Delivered | B28: 83 | D28: U cut | E28: =F28*$B$2 -> 2710 | F28: 0.012617562 | G28: =G27+F28 -> 0.90222553 | I28: Grand Total | J28: 39430 | K28: 1 | N28: U cut | O28: 2710 | P28: =O28/$O$46 -> 0.012617562 | Q28: =Q27+P28 -> 0.90222553 | R28: =IF(Q28<=70%,"A",IF(Q28<=90%,"B","C")) -> C | T28: Monthly Trend analysis-Beauty | Z28: Wine Facial | AB28: 7 | AC28: 7 | AE28: Below Min(Bargain) | AF28: 202 | AJ28: Straight cut | AL28: 1 | AM28: 5 | AO28: Repeat | AP28: 1 | AQ28: 12 | AR28: 6
A29: Unique Services Offered | B29: 14 | D29: Head Massage | E29: =F29*$B$2 -> 2670 | F29: 0.012431325 | G29: =G28+F29 -> 0.91465686 | N29: Head Massage | O29: 2670 | P29: =O29/$O$46 -> 0.012431325 | Q29: =Q28+P29 -> 0.91465686 | R29: =IF(Q29<=70%,"A",IF(Q29<=90%,"B","C")) -> C | T29: Month-year | U29: New | V29: Repeat | Z29: Baby Shower Makeup | AB29: 2 | AC29: 2 | AE29: Within Range | AF29: 253 | AJ29: Blowdry | AL29: 1 | AO29: Layer cut | AQ29: 12 | AR29: 14
D30: Hair coloring full | E30: =F30*$B$2 -> 2600 | F30: 0.01210541 | G30: =G29+F30 -> 0.92676227 | I30: Customer Revenue by Category (New vs Repeat) | N30: Hair coloring full | O30: 2600 | P30: =O30/$O$46 -> 0.01210541 | Q30: =Q29+P30 -> 0.92676227 | R30: =IF(Q30<=70%,"A",IF(Q30<=90%,"B","C")) -> C | T30: Jul-2024 | U30: 7 | V30: 32 | Z30: Green Tea Facial | AB30: 4 | AC30: 4 | AJ30: Vitamin C Facial | AK30: 1 | AL30: 1 | AM30: 4 | AO30: New | AR30: 1
D31: Lice treatment | E31: =F31*$B$2 -> 2000 | F31: 0.009311854 | G31: =G30+F31 -> 0.93607412 | I31: Category | J31: New | K31: Repeat | L31: Grand Total | N31: Lice treatment | O31: 2000 | P31: =O31/$O$46 -> 0.009311854 | Q31: =Q30+P31 -> 0.93607412 | R31: =IF(Q31<=70%,"A",IF(Q31<=90%,"B","C")) -> C | T31: Aug-2024 | U31: 11 | V31: 48 | Z31: Feather cut | AB31: 1 | AC31: 1 | AE31: Pricing Behavior - Tailoring | AJ31: Pedicure | AL31: 1 | AM31: 1 | AO31: Repeat | AQ31: 12 | AR31: 13
D32: Basic cut | E32: =F32*$B$2 -> 1800 | F32: 0.0083806686 | G32: =G31+F32 -> 0.94445479 | I32: Beauty service | J32: 34730 | K32: 180050 | L32: 214780 | N32: Basic cut | O32: 1800 | P32: =O32/$O$46 -> 0.0083806686 | Q32: =Q31+P32 -> 0.94445479 | R32: =IF(Q32<=70%,"A",IF(Q32<=90%,"B","C")) -> C | T32: Sep-2024 | U32: 10 | V32: 38 | Z32: Hair coloring full | AB32: 2 | AC32: 2 | AE32: price behavior | AF32: Count of Pricing Behavior | AJ32: Butterfly cut | AL32: 1 | AM32: 1 | AO32: De-tan Facial | AQ32: 7 | AR32: 1
D33: Straight cut | E33: =F33*$B$2 -> 1770 | F33: 0.0082409908 | G33: =G32+F33 -> 0.95269578 | I33: Tailoring service | J33: 23475 | K33: 15955 | L33: 39430 | N33: Straight cut | O33: 1770 | P33: =O33/$O$46 -> 0.0082409908 | Q33: =Q32+P33 -> 0.95269578 | R33: =IF(Q33<=70%,"A",IF(Q33<=90%,"B","C")) -> C | T33: Oct-2024 | U33: 8 | V33: 36 | Z33: Bridal Makeup | AB33: 1 | AC33: 1 | AE33: Above Max | AF33: 18 | AJ33: Hair wash | AK33: 4 | AL33: 1 | AM33: 6 | AO33: New | AQ33: 1
D34: Hand Wax | E34: =F34*$B$2 -> 1750 | F34: 0.0081478722 | G34: =G33+F34 -> 0.96084365 | I34: Grand Total | J34: 58205 | K34: 196005 | L34: 254210 | N34: Hand Wax | O34: 1750 | P34: =O34/$O$46 -> 0.0081478722 | Q34: =Q33+P34 -> 0.96084365 | R34: =IF(Q34<=70%,"A",IF(Q34<=90%,"B","C")) -> C | T34: Nov-2024 | U34: 11 | V34: 32 | Z34: Blowdry | AB34: 1 | AC34: 1 | AE34: Below Min(Bargain) | AF34: 4 | AJ34: Baby cut | AL34: 1 | AM34: 3 | AO34: Repeat | AQ34: 6 | AR34: 1
D35: Face Wax | E35: =F35*$B$2 -> 1460 | F35: 0.0067976534 | G35: =G34+F35 -> 0.96764131 | N35: Face Wax | O35: 1460 | P35: =O35/$O$46 -> 0.0067976534 | Q35: =Q34+P35 -> 0.96764131 | R35: =IF(Q35<=70%,"A",IF(Q35<=90%,"B","C")) -> C | T35: Dec-2024 | U35: 4 | V35: 26 | Z35: Ear piercing | AB35: 1 | AC35: 1 | AE35: Within Range | AF35: 61 | AJ35: Party Makeup | AM35: 1 | AO35: Cleanup | AQ35: 6 | AR35: 4
D36: Butterfly cut | E36: =F36*$B$2 -> 1160 | F36: 0.0054008753 | G36: =G35+F36 -> 0.97304218 | N36: Butterfly cut | O36: 1160 | P36: =O36/$O$46 -> 0.0054008753 | Q36: =Q35+P36 -> 0.97304218 | R36: =IF(Q36<=70%,"A",IF(Q36<=90%,"B","C")) -> C | T36: Jan-2025 | U36: 7 | V36: 51 | Z36: Smoothening | AB36: 1 | AC36: 1 | AJ36: Straightening | AM36: 1 | AO36: Repeat | AQ36: 6 | AR36: 4
D37: Pedicure | E37: =F37*$B$2 -> 1100 | F37: 0.0051215197 | G37: =G36+F37 -> 0.9781637 | N37: Pedicure | O37: 1100 | P37: =O37/$O$46 -> 0.0051215197 | Q37: =Q36+P37 -> 0.9781637 | R37: =IF(Q37<=70%,"A",IF(Q37<=90%,"B","C")) -> C | T37: Feb-2025 | U37: 4 | V37: 33 | Z37: Full Arms Wax | AB37: 1 | AC37: 1 | AE37: Revenue Loss (Beauty and Tailoring) | AJ37: Baby Shower Makeup | AM37: 2 | AO37: Golden Facial | AP37: 2 | AQ37: 5 | AR37: 2
D38: Straightening | E38: =F38*$B$2 -> 900 | F38: 0.0041903343 | G38: =G37+F38 -> 0.98235404 | N38: Straightening | O38: 900 | P38: =O38/$O$46 -> 0.0041903343 | Q38: =Q37+P38 -> 0.98235404 | R38: =IF(Q38<=70%,"A",IF(Q38<=90%,"B","C")) -> C | T38: Mar-2025 | U38: 8 | V38: 26 | Z38: Straightening | AB38: 1 | AC38: 1 | AE38: Service | AF38: Sum of Revenue Loss | AJ38: Green Tea Facial | AM38: 4 | AO38: New | AP38: 2 | AQ38: 1 | AR38: 1
D39: Feather cut | E39: =F39*$B$2 -> 800 | F39: 0.0037247416 | G39: =G38+F39 -> 0.98607878 | N39: Feather cut | O39: 800 | P39: =O39/$O$46 -> 0.0037247416 | Q39: =Q38+P39 -> 0.98607878 | R39: =IF(Q39<=70%,"A",IF(Q39<=90%,"B","C")) -> C | T39: Apr-2025 | U39: 9 | V39: 47 | Z39: Bleach | AB39: 14 | AC39: 14 | AE39: Beauty service | AF39: 32070 | AJ39: Lice treatment | AM39: 1 | AO39: Repeat | AQ39: 4 | AR39: 1
D40: Baby cut | E40: =F40*$B$2 -> 670 | F40: 0.0031194711 | G40: =G39+F40 -> 0.98919825 | N40: Baby cut | O40: 670 | P40: =O40/$O$46 -> 0.0031194711 | Q40: =Q39+P40 -> 0.98919825 | R40: =IF(Q40<=70%,"A",IF(Q40<=90%,"B","C")) -> C | T40: May-2025 | U40: 4 | V40: 26 | Z40: Under Arm Wax | AB40: 1 | AC40: 1 | AE40: Tailoring service | AF40: 280 | AJ40: Simple Makeup | AM40: 2 | AO40: Bleach | AQ40: 5 | AR40: 9
...

Sheet chart data
